import axios, {AxiosError} from "../lib/axios";

export const SAVE_QUESTIONNAIRE_START = "SAVE_QUESTIONNAIRE_START";
export const SAVE_QUESTIONNAIRE_SUCCESS = "SAVE_QUESTIONNAIRE_SUCCESS";
export const SAVE_QUESTIONNAIRE_ERROR = "SAVE_QUESTIONNAIRE_ERROR";

// TODO: add tests and type checking
export function saveQuestionnaireAnswers (answers, userId, siteId, questionnaire, visitId) {
    return async dispatch => {
        try {
            dispatch({type: SAVE_QUESTIONNAIRE_START});
            return axios.post("/answers", {
                answers,
                userId,
                siteId,
                questionId: questionnaire._id,
                category: questionnaire.category,
                type: questionnaire.type,
                visitId
            })
            .then(res => {
                dispatch({type: SAVE_QUESTIONNAIRE_SUCCESS, payload: res.data});
            })
            .catch(err => {
                /*
                *   We want to dispatch a SAVE_SURVEY_ERROR action only when
                *   `axios.post` fails (the error is an AxiosError). In all
                *   other cases we rethrow the error.
                */
                if (err instanceof AxiosError) {
                    dispatch({
                        type: SAVE_QUESTIONNAIRE_ERROR,
                        payload: err,
                        error: true
                    });
                } else {
                    throw err;
                }
            });
        } catch (err) {
            /*
            *   We cannot recover from a dispatch error. Therefore we only
            *   log it.
            */
            console.error(err);
        }
    };
}
